Workbook

Sheet Operations
A1: 🎪 SpringSmash 2026 — Operations Budget
A2: Department: Operations Team | Event Date: May 14, 2026 | Last Updated: ___________ | Prepared By: ___________
A3: Category | B3: Item / Description | C3: Vendor / Source | D3: Qty | E3: Cost per Unit ($) | F3: Total Cost ($) | G3: Status | H3: Notes
A4: ▸ 🎈 Inflatables
A5: Inflatables | B5: 40 ft tropical waterslide slip and slide | D5: 1 | E5: 1999 | F5: =IF(D5="","-",D5*E5)
B6: Rugged Warrior challenege | D6: 1 | E6: 1799 | F6: =IF(D6="","-",D6*E6)
B7: Slip and Slide | D7: 1 | E7: 399 | F7: =IF(D7="","-",D7*E7)
F8: =IF(D8="","-",D8*E8)
F9: =IF(D9="","-",D9*E9)
F10: =IF(D10="","-",D10*E10)
A11: Subtotal — 🎈 Inflatables | F11: =SUM(F5:F10)
A13: ▸ 🎮 Games & Activities
A14: Games & Activities | B14: Dunk Tank | D14: 1 | E14: 449 | F14: =IF(D14="","-",D14*E14)
B15: Wrecking Ball | D15: 1 | E15: 599 | F15: =IF(D15="","-",D15*E15)
F16: =IF(D16="","-",D16*E16)
F17: =IF(D17="","-",D17*E17)
F18: =IF(D18="","-",D18*E18)
F19: =IF(D19="","-",D19*E19)
A20: Subtotal — 🎮 Games & Activities | F20: =SUM(F14:F19)
A22: ▸ 🌸 Decorations
A23: Decorations | F23: =IF(D23="","-",D23*E23)
F24: =IF(D24="","-",D24*E24)
F25: =IF(D25="","-",D25*E25)
F26: =IF(D26="","-",D26*E26)
A27: Subtotal — 🌸 Decorations | F27: =SUM(F23:F26)
A29: ▸ 🍔 Food & Beverage – Dining Hall BBQ
A30: Food – Dining Hall | F30: =IF(D30="","-",D30*E30)
F31: =IF(D31="","-",D31*E31)
F32: =IF(D32="","-",D32*E32)
F33: =IF(D33="","-",D33*E33)
F34: =IF(D34="","-",D34*E34)
F35: =IF(D35="","-",D35*E35)
A36: Subtotal — 🍔 Food & Beverage – Dining Hall BBQ | F36: =SUM(F30:F35)
A38: ▸ 🍿 Food & Beverage – Additional Items
A39: Food – Additional | B39: Snowcone Machine | D39: 2 | E39: 125 | F39: =IF(D39="","-",D39*E39)
B40: Snowcone Servings | D40: 500 | E40: 0.7 | F40: =IF(D40="","-",D40*E40)
B41: Freezies | D41: 1 | E41: 300 | F41: =IF(D41="","-",D41*E41)
F42: =IF(D42="","-",D42*E42)
F43: =IF(D43="","-",D43*E43)
F44: =IF(D44="","-",D44*E44)
...

Sheet Marketing
A1: 🎪 SpringSmash 2026 — Marketing & Sponsorship Budget
A2: Department: Marketing Team | Event Date: May 14, 2026 | Last Updated: ___________ | Prepared By: ___________
A3: Category | B3: Item / Description | C3: Vendor / Source | D3: Qty | E3: Cost per Unit ($) | F3: Total Cost ($) | G3: Status | H3: Notes
A4: ▸ 🎨 Branding (Logo / Theme / Slogan)
A5: Branding | F5: =IF(D5="","-",D5*E5)
F6: =IF(D6="","-",D6*E6)
F7: =IF(D7="","-",D7*E7)
A8: Subtotal — 🎨 Branding (Logo / Theme / Slogan) | F8: =SUM(F5:F7)
A10: ▸ 👕 Merchandise & Swag
A11: Merchandise / Swag | B11: T-Shirts | D11: 1 | E11: 3600 | F11: =IF(D11="","-",D11*E11)
F12: =IF(D12="","-",D12*E12)
F13: =IF(D13="","-",D13*E13)
F14: =IF(D14="","-",D14*E14)
F15: =IF(D15="","-",D15*E15)
F16: =IF(D16="","-",D16*E16)
A17: Subtotal — 👕 Merchandise & Swag | F17: =SUM(F11:F16)
A19: ▸ 🏆 Prize Structure
A20: Prize Structure | F20: =IF(D20="","-",D20*E20)
F21: =IF(D21="","-",D21*E21)
F22: =IF(D22="","-",D22*E22)
F23: =IF(D23="","-",D23*E23)
F24: =IF(D24="","-",D24*E24)
F25: =IF(D25="","-",D25*E25)
F26: =IF(D26="","-",D26*E26)
F27: =IF(D27="","-",D27*E27)
A28: Subtotal — 🏆 Prize Structure | F28: =SUM(F20:F27)
A30: ▸ 📣 In-Person Marketing Campaign (4-Week)
A31: In-Person Campaign | F31: =IF(D31="","-",D31*E31)
F32: =IF(D32="","-",D32*E32)
F33: =IF(D33="","-",D33*E33)
F34: =IF(D34="","-",D34*E34)
F35: =IF(D35="","-",D35*E35)
A36: Subtotal — 📣 In-Person Marketing Campaign (4-Week) | F36: =SUM(F31:F35)
A38: ▸ 📱 Online / Social Media Campaign (4-Week)
A39: Online Campaign | F39: =IF(D39="","-",D39*E39)
F40: =IF(D40="","-",D40*E40)
F41: =IF(D41="","-",D41*E41)
F42: =IF(D42="","-",D42*E42)
F43: =IF(D43="","-",D43*E43)
A44: Subtotal — 📱 Online / Social Media Campaign (4-Week) | F44: =SUM(F39:F43)
...

Sheet Finance
A1: 💰 SpringSmash 2026 — Finance & Fundraising Overview
A2: Department: Finance & Fundraising | Event: SpringSmash 2026 | Event Date: May 14, 2026 | Last Updated: ___________
A3: 📥 SECTION A — SPONSORSHIP REVENUE
A4: Sponsor Name | B4: Sponsorship Tier | C4: Contact Person | D4: Amount Pledged ($) | E4: Amount Received ($) | F4: Outstanding ($) | G4: Date Received | H4: Recognition Promised | I4: Status | J4: Notes
F5: =IF(D5="","-",D5-E5)
F6: =IF(D6="","-",D6-E6)
F7: =IF(D7="","-",D7-E7)
F8: =IF(D8="","-",D8-E8)
F9: =IF(D9="","-",D9-E9)
F10: =IF(D10="","-",D10-E10)
A11: TOTAL SPONSORSHIP REVENUE | E11: =SUM(E5:E10)
A13: 📈 SECTION B — JUMPSTART FUNDRAISING REVENUE
A14: Week / Period | B14: Top Fundraiser | C14: Fundraising Target ($) | D14: Actual Raised ($) | E14: % of Target | F14: Campaign Activity | G14: Platform | H14: Date | I14: Status | J14: Notes
A15: Week 1 | E15: =IF(C15=0,"-",D15/C15)
A16: Week 2 | E16: =IF(C16=0,"-",D16/C16)
A17: Week 3 | E17: =IF(C17=0,"-",D17/C17)
A18: Week 4 | E18: =IF(C18=0,"-",D18/C18)
A19: Campaign Total | E19: =IF(C19=0,"-",D19/C19)
A20: TOTAL FUNDRAISING REVENUE | D20: =SUM(D15:D19)
A22: 🏆 SECTION C — PRIZE COSTS
A23: Prize Category | B23: Award / Description | C23: Criteria | D23: Qty | E23: Unit Cost ($) | F23: Total Cost ($) | G23: Vendor / Source | H23: Status | I23: Delivery Date | J23: Notes
A24: Weekly Top Donor (Weekly prizes) | F24: =IF(D24="","-",D24*E24)
A25: Top 3 US Advisory | F25: =IF(D25="","-",D25*E25)
A26: Top 3 MS Advisory | F26: =IF(D26="","-",D26*E26)
A27: Top 3 Individual Donors | F27: =IF(D27="","-",D27*E27)
A28: Top 20 Donors – VIP / Fast Pass | F28: =IF(D28="","-",D28*E28)
A29: Boarder House Award | F29: =IF(D29="","-",D29*E29)
A30: Day Student House Award | F30: =IF(D30="","-",D30*E30)
A31: Raffle Prize #1 | F31: =IF(D31="","-",D31*E31)
A32: Raffle Prize #2 | F32: =IF(D32="","-",D32*E32)
A33: Raffle Prize #3 | F33: =IF(D33="","-",D33*E33)
A34: TOTAL PRIZE COSTS | F34: =SUM(F24:F33)
A36: 📣 SECTION D — CAMPAIGN & MARKETING COSTS
A37: Week | B37: Activity Name | C37: Type (Online/In-Person) | D37: Target Audience | E37: Qty | F37: Estimated Cost ($) | G37: Actual Cost ($) | H37: Vendor / Platform | I37: Status | J37: Notes
A38: Week 1
A39: Week 1
A40: Week 2
A41: Week 2
A42: Week 3
A43: Week 3
...

Sheet Sponsorship
A1: 🤝 SpringSmash 2026 — Sponsorship Tracker
A2: Department: Marketing & Finance | Event: SpringSmash 2026 | Event Date: May 14, 2026 | Last Updated: ___________ | Prepared By: ___________
A3: # | B3: Sponsor Name | C3: Sponsorship Tier | D3: Contribution Amount ($) | E3: Status | F3: Date Confirmed | G3: Recognition Promised | H3: Notes
A4: 📋 Confirmed & Pipeline Sponsors
A5: 1 | B5: McAlpine Ford | C5: Title Sponsor | E5: ⏳ Pending | G5: Logo on banner, MC mention, social post
A6: 2 | B6: JDL Realty | C6: Gold Sponsor | E6: ⏳ Pending | G6: Logo on banner, event signage
A7: 3 | B7: Mimi's Swim School | C7: Silver Sponsor | D7: 1000 | E7: 📋 Tentative | G7: Logo on banner, social post | H7: ~$1,000 estimated — confirm closer to date
A8: 4 | B8: Orange Theory Fitness | C8: Silver Sponsor | E8: ⏳ Pending | G8: Logo on banner, promo table
A9: 5 | B9: HQ Wellness | C9: Community Sponsor | E9: ⏳ Pending | G9: Social mention, program listing
A10: 6 | B10: Cwench | C10: Product Sponsor | E10: ⏳ Pending | G10: Product sampling/signage at event
A11: 7
A12: 8
A13: 9
A14: 💰 TOTAL SPONSORSHIP REVENUE | D14: =SUM(D5:D13)
A16: 📌 STATUS KEY: ✅ Confirmed = Cheque/transfer received | ⏳ Pending = Verbal/email commitment, awaiting confirmation | 📋 Tentative = Estimated, not yet confirmed
A17: 📌 LEGEND: Blue text = Input cells (enter your data) | Black text = Auto-calculated | D14 = Used in MASTER BUDGET via formula

Sheet MASTER BUDGET
A1: 📊 SpringSmash 2026 · MASTER BUDGET
A2: Event: SpringSmash 2026 | Charity: Jumpstart | Date: May 14, 2026 | School: McEwen | Supervisor: Mr. Ludwig | Prepared By: ___________ | Updated: ___________
A4: 🔢 AT-A-GLANCE SNAPSHOT
B5: 💰 TOTAL REVENUE | E5: 📤 TOTAL EXPENSES
B6: =F21 | E6: =F29
B8: 🏅 OPERATIONS BUDGET | E8: 🎨 MARKETING BUDGET
B9: =Operations!F94 | E9: =Marketing!F66
B10: 🏁 NET FUNDS RAISED / (DEFICIT)
B11: =F33-F34
A13: 📋 HOW TO USE THIS WORKBOOK
B14: 1. Operations Tab → Enter all event costs: inflatables, food, equipment, sports gear, VIP, DJ, health & safety 2. Marketing Tab → Enter branding, swag, prizes, campaigns, sponsorship materials, press/website 3. Finance Tab → Enter sponsorship revenue received and week-by-week fundraising data 4. Sponsorship Tab → Track all sponsors, tiers, amounts, and confirmation status 5. This Sheet → All totals auto-update — no manual entry needed here 🔵 Blue text = Data entry cells · ⚫ Black text = Auto-calculated · 🟢 Green text = Cross-sheet link
A16: ➕ REVENUE
B17: Section | C17: Line Item | D17: Description / Source | F17: Amount ($)
A18: Revenue | B18: Sponsorship Revenue | C18: Linked from Sponsorship sheet (cell D14) | F18: =Sponsorship!D14
A19: Revenue | B19: Jumpstart Fundraising Revenue | C19: Total online + offline donations raised via Jumpstart — enter when available
A20: Revenue | B20: Other Revenue | C20: Ticket sales, additional donations, grants, etc. (enter if applicable)
A21: TOTAL REVENUE | F21: =F18+F19+F20
A23: ➖ EXPENSES
B24: Section | C24: Line Item | D24: Description / Source | F24: Amount ($)
A25: Expenses | B25: Operations Costs | C25: Linked from Operations sheet — all 11 subcategories (Operations!F94) | F25: =Operations!F94
A26: Expenses | B26: Marketing Costs | C26: Linked from Marketing sheet — all 8 subcategories (Marketing!F66) | F26: =Marketing!F66
A27: Expenses | B27: Finance / Prize & Campaign Costs | C27: Linked from Finance sheet — prize pool (G58) + campaign costs (G59) | F27: =Finance!G58+Finance!G59
A28: Expenses | B28: Contingency Reserve (5%) | C28: Recommended 5% buffer applied to all operational expenses | F28: =(F25+F26+F27)*0.05
A29: TOTAL EXPENSES | F29: =F25+F26+F27+F28
A31: 📋 FINANCIAL SUMMARY
B32: Section | C32: Line Item | D32: Description / Source | F32: Amount ($)
A33: Summary | B33: Total Revenue | C33: Sum of all revenue streams | F33: =F21
A34: Summary | B34: Total Expenses | C34: Sum of all expense streams including contingency | F34: =F29
A35: Summary | B35: Variance (Revenue − Expenses) | C35: Positive = surplus for Jumpstart · Negative = deficit requiring action | F35: =F33-F34
A37: 🏁 NET PROFIT / (LOSS) | E37: =F33-F34
A39: 🚦 BUDGET STATUS GUIDE
A40: ✅ PROFITABLE | C40: Net Profit > $0 | D40: Revenue exceeds expenses — surplus funds go directly to Jumpstart.
A41: ⚖️ BREAK-EVEN | C41: Net Profit ≈ $0 | D41: Revenue covers all costs. No surplus or deficit — review for optimisation.
A42: ⚠️ OVER BUDGET | C42: Net Profit < $0 | D42: Expenses exceed revenue. Reduce costs or increase sponsorship/fundraising.
A44: 🔗 FORMULA CROSS-REFERENCE
B45: Line Item | C45: Excel Formula | D45: Data Source / Sheet | F45: Notes
A46: Sponsorship Revenue | C46: =Sponsorship!D14 | D46: Sponsorship sheet | E46: Sum of all confirmed + tentative amounts in col D
A47: Operations Total | C47: =Operations!F94 | D47: Operations sheet | E47: Grand total of all 11 operational sections
A48: Marketing Total | C48: =Marketing!F66 | D48: Marketing sheet | E48: Grand total of all 8 marketing sections
A49: Finance (Prize + Campaign) | C49: =Finance!G58+Finance!G59 | D49: Finance sheet | E49: Prize costs row + Campaign costs row
...
